Workbook

Sheet Main
A1: Name (DisplayName) | B1: Contact Number | C1: Zone | D1: Connection | E1: Location | F1: Info | G1: Info_Date | H1: Invite | I1: Invite_Date | J1: Plan | K1: Comments | L1: Notes
A2: Samsung Helpline | B2: 1800407267864 | F2: =IFERROR(LOOKUP(2,1/('Weekly Tracker'!$E$2:$E$766=$A2)/('Weekly Tracker'!$F$2:$F$766<>""),'Weekly Tracker'!$F$2:$F$766),"") | G2: =IF(F2<>"",LOOKUP(2,1/('Weekly Tracker'!$E$2:$E$766=$A2)/('Weekly Tracker'!$F$2:$F$766<>""),'Weekly Tracker'!$G$2:$G$766),"") | H2: =IFERROR(LOOKUP(2,1/('Weekly Tracker'!$E$2:$E$766=$A2)/('Weekly Tracker'!$H$2:$H$766<>""),'Weekly Tracker'!$H$2:$H$766),"") | I2: =IF(H2<>"",LOOKUP(2,1/('Weekly Tracker'!$E$2:$E$766=$A2)/('Weekly Tracker'!$H$2:$H$766<>""),'Weekly Tracker'!$I$2:$I$766),"") | J2: =IFERROR(LOOKUP(2,1/('Weekly Tracker'!$E$2:$E$766=$A2)/('Weekly Tracker'!$J$2:$J$766<>""),'Weekly Tracker'!$J$2:$J$766),"") | K2: =IFERROR(LOOKUP(2,1/('Weekly Tracker'!$E$2:$E$766=$A2)/('Weekly Tracker'!$N$2:$N$766<>""),'Weekly Tracker'!$N$2:$N$766),"") | L2: =IFERROR(LOOKUP(2,1/('Weekly Tracker'!$E$2:$E$766=$A2)/('Weekly Tracker'!$O$2:$O$766<>""),'Weekly Tracker'!$O$2:$O$766),"")
A3: Ragul Urja | B3: 917806971707, +91 78069 71707 | F3: =IFERROR(LOOKUP(2,1/('Weekly Tracker'!$E$2:$E$766=$A3)/('Weekly Tracker'!$F$2:$F$766<>""),'Weekly Tracker'!$F$2:$F$766),"") | G3: =IF(F3<>"",LOOKUP(2,1/('Weekly Tracker'!$E$2:$E$766=$A3)/('Weekly Tracker'!$F$2:$F$766<>""),'Weekly Tracker'!$G$2:$G$766),"") | H3: =IFERROR(LOOKUP(2,1/('Weekly Tracker'!$E$2:$E$766=$A3)/('Weekly Tracker'!$H$2:$H$766<>""),'Weekly Tracker'!$H$2:$H$766),"") | I3: =IF(H3<>"",LOOKUP(2,1/('Weekly Tracker'!$E$2:$E$766=$A3)/('Weekly Tracker'!$H$2:$H$766<>""),'Weekly Tracker'!$I$2:$I$766),"") | J3: =IFERROR(LOOKUP(2,1/('Weekly Tracker'!$E$2:$E$766=$A3)/('Weekly Tracker'!$J$2:$J$766<>""),'Weekly Tracker'!$J$2:$J$766),"") | K3: =IFERROR(LOOKUP(2,1/('Weekly Tracker'!$E$2:$E$766=$A3)/('Weekly Tracker'!$N$2:$N$766<>""),'Weekly Tracker'!$N$2:$N$766),"") | L3: =IFERROR(LOOKUP(2,1/('Weekly Tracker'!$E$2:$E$766=$A3)/('Weekly Tracker'!$O$2:$O$766<>""),'Weekly Tracker'!$O$2:$O$766),"")
A4: Rajesh ramadoss Urja | B4: 919952925095 | F4: =IFERROR(LOOKUP(2,1/('Weekly Tracker'!$E$2:$E$766=$A4)/('Weekly Tracker'!$F$2:$F$766<>""),'Weekly Tracker'!$F$2:$F$766),"") | G4: =IF(F4<>"",LOOKUP(2,1/('Weekly Tracker'!$E$2:$E$766=$A4)/('Weekly Tracker'!$F$2:$F$766<>""),'Weekly Tracker'!$G$2:$G$766),"") | H4: =IFERROR(LOOKUP(2,1/('Weekly Tracker'!$E$2:$E$766=$A4)/('Weekly Tracker'!$H$2:$H$766<>""),'Weekly Tracker'!$H$2:$H$766),"") | I4: =IF(H4<>"",LOOKUP(2,1/('Weekly Tracker'!$E$2:$E$766=$A4)/('Weekly Tracker'!$H$2:$H$766<>""),'Weekly Tracker'!$I$2:$I$766),"") | J4: =IFERROR(LOOKUP(2,1/('Weekly Tracker'!$E$2:$E$766=$A4)/('Weekly Tracker'!$J$2:$J$766<>""),'Weekly Tracker'!$J$2:$J$766),"") | K4: =IFERROR(LOOKUP(2,1/('Weekly Tracker'!$E$2:$E$766=$A4)/('Weekly Tracker'!$N$2:$N$766<>""),'Weekly Tracker'!$N$2:$N$766),"") | L4: =IFERROR(LOOKUP(2,1/('Weekly Tracker'!$E$2:$E$766=$A4)/('Weekly Tracker'!$O$2:$O$766<>""),'Weekly Tracker'!$O$2:$O$766),"")
A5: Rajesh Past Urja | B5: 919790921712 | F5: =IFERROR(LOOKUP(2,1/('Weekly Tracker'!$E$2:$E$766=$A5)/('Weekly Tracker'!$F$2:$F$766<>""),'Weekly Tracker'!$F$2:$F$766),"") | G5: =IF(F5<>"",LOOKUP(2,1/('Weekly Tracker'!$E$2:$E$766=$A5)/('Weekly Tracker'!$F$2:$F$766<>""),'Weekly Tracker'!$G$2:$G$766),"") | H5: =IFERROR(LOOKUP(2,1/('Weekly Tracker'!$E$2:$E$766=$A5)/('Weekly Tracker'!$H$2:$H$766<>""),'Weekly Tracker'!$H$2:$H$766),"") | I5: =IF(H5<>"",LOOKUP(2,1/('Weekly Tracker'!$E$2:$E$766=$A5)/('Weekly Tracker'!$H$2:$H$766<>""),'Weekly Tracker'!$I$2:$I$766),"") | J5: =IFERROR(LOOKUP(2,1/('Weekly Tracker'!$E$2:$E$766=$A5)/('Weekly Tracker'!$J$2:$J$766<>""),'Weekly Tracker'!$J$2:$J$766),"") | K5: =IFERROR(LOOKUP(2,1/('Weekly Tracker'!$E$2:$E$766=$A5)/('Weekly Tracker'!$N$2:$N$766<>""),'Weekly Tracker'!$N$2:$N$766),"") | L5: =IFERROR(LOOKUP(2,1/('Weekly Tracker'!$E$2:$E$766=$A5)/('Weekly Tracker'!$O$2:$O$766<>""),'Weekly Tracker'!$O$2:$O$766),"")
A6: Ragul Hit Urja | B6: 919944401970 | F6: =IFERROR(LOOKUP(2,1/('Weekly Tracker'!$E$2:$E$766=$A6)/('Weekly Tracker'!$F$2:$F$766<>""),'Weekly Tracker'!$F$2:$F$766),"") | G6: =IF(F6<>"",LOOKUP(2,1/('Weekly Tracker'!$E$2:$E$766=$A6)/('Weekly Tracker'!$F$2:$F$766<>""),'Weekly Tracker'!$G$2:$G$766),"") | H6: =IFERROR(LOOKUP(2,1/('Weekly Tracker'!$E$2:$E$766=$A6)/('Weekly Tracker'!$H$2:$H$766<>""),'Weekly Tracker'!$H$2:$H$766),"") | I6: =IF(H6<>"",LOOKUP(2,1/('Weekly Tracker'!$E$2:$E$766=$A6)/('Weekly Tracker'!$H$2:$H$766<>""),'Weekly Tracker'!$I$2:$I$766),"") | J6: =IFERROR(LOOKUP(2,1/('Weekly Tracker'!$E$2:$E$766=$A6)/('Weekly Tracker'!$J$2:$J$766<>""),'Weekly Tracker'!$J$2:$J$766),"") | K6: =IFERROR(LOOKUP(2,1/('Weekly Tracker'!$E$2:$E$766=$A6)/('Weekly Tracker'!$N$2:$N$766<>""),'Weekly Tracker'!$N$2:$N$766),"") | L6: =IFERROR(LOOKUP(2,1/('Weekly Tracker'!$E$2:$E$766=$A6)/('Weekly Tracker'!$O$2:$O$766<>""),'Weekly Tracker'!$O$2:$O$766),"")
A7: Rajesh FB | B7: 8428885607, 84288 85607 | F7: =IFERROR(LOOKUP(2,1/('Weekly Tracker'!$E$2:$E$766=$A7)/('Weekly Tracker'!$F$2:$F$766<>""),'Weekly Tracker'!$F$2:$F$766),"") | G7: =IF(F7<>"",LOOKUP(2,1/('Weekly Tracker'!$E$2:$E$766=$A7)/('Weekly Tracker'!$F$2:$F$766<>""),'Weekly Tracker'!$G$2:$G$766),"") | H7: =IFERROR(LOOKUP(2,1/('Weekly Tracker'!$E$2:$E$766=$A7)/('Weekly Tracker'!$H$2:$H$766<>""),'Weekly Tracker'!$H$2:$H$766),"") | I7: =IF(H7<>"",LOOKUP(2,1/('Weekly Tracker'!$E$2:$E$766=$A7)/('Weekly Tracker'!$H$2:$H$766<>""),'Weekly Tracker'!$I$2:$I$766),"") | J7: =IFERROR(LOOKUP(2,1/('Weekly Tracker'!$E$2:$E$766=$A7)/('Weekly Tracker'!$J$2:$J$766<>""),'Weekly Tracker'!$J$2:$J$766),"") | K7: =IFERROR(LOOKUP(2,1/('Weekly Tracker'!$E$2:$E$766=$A7)/('Weekly Tracker'!$N$2:$N$766<>""),'Weekly Tracker'!$N$2:$N$766),"") | L7: =IFERROR(LOOKUP(2,1/('Weekly Tracker'!$E$2:$E$766=$A7)/('Weekly Tracker'!$O$2:$O$766<>""),'Weekly Tracker'!$O$2:$O$766),"")
A8: Rakesh Urja | B8: 919551130445, +91 95511 30445 | F8: =IFERROR(LOOKUP(2,1/('Weekly Tracker'!$E$2:$E$766=$A8)/('Weekly Tracker'!$F$2:$F$766<>""),'Weekly Tracker'!$F$2:$F$766),"") | G8: =IF(F8<>"",LOOKUP(2,1/('Weekly Tracker'!$E$2:$E$766=$A8)/('Weekly Tracker'!$F$2:$F$766<>""),'Weekly Tracker'!$G$2:$G$766),"") | H8: =IFERROR(LOOKUP(2,1/('Weekly Tracker'!$E$2:$E$766=$A8)/('Weekly Tracker'!$H$2:$H$766<>""),'Weekly Tracker'!$H$2:$H$766),"") | I8: =IF(H8<>"",LOOKUP(2,1/('Weekly Tracker'!$E$2:$E$766=$A8)/('Weekly Tracker'!$H$2:$H$766<>""),'Weekly Tracker'!$I$2:$I$766),"") | J8: =IFERROR(LOOKUP(2,1/('Weekly Tracker'!$E$2:$E$766=$A8)/('Weekly Tracker'!$J$2:$J$766<>""),'Weekly Tracker'!$J$2:$J$766),"") | K8: =IFERROR(LOOKUP(2,1/('Weekly Tracker'!$E$2:$E$766=$A8)/('Weekly Tracker'!$N$2:$N$766<>""),'Weekly Tracker'!$N$2:$N$766),"") | L8: =IFERROR(LOOKUP(2,1/('Weekly Tracker'!$E$2:$E$766=$A8)/('Weekly Tracker'!$O$2:$O$766<>""),'Weekly Tracker'!$O$2:$O$766),"")
A9: Vinoth Mech | B9: 8015927970 | F9: =IFERROR(LOOKUP(2,1/('Weekly Tracker'!$E$2:$E$766=$A9)/('Weekly Tracker'!$F$2:$F$766<>""),'Weekly Tracker'!$F$2:$F$766),"") | G9: =IF(F9<>"",LOOKUP(2,1/('Weekly Tracker'!$E$2:$E$766=$A9)/('Weekly Tracker'!$F$2:$F$766<>""),'Weekly Tracker'!$G$2:$G$766),"") | H9: =IFERROR(LOOKUP(2,1/('Weekly Tracker'!$E$2:$E$766=$A9)/('Weekly Tracker'!$H$2:$H$766<>""),'Weekly Tracker'!$H$2:$H$766),"") | I9: =IF(H9<>"",LOOKUP(2,1/('Weekly Tracker'!$E$2:$E$766=$A9)/('Weekly Tracker'!$H$2:$H$766<>""),'Weekly Tracker'!$I$2:$I$766),"") | J9: =IFERROR(LOOKUP(2,1/('Weekly Tracker'!$E$2:$E$766=$A9)/('Weekly Tracker'!$J$2:$J$766<>""),'Weekly Tracker'!$J$2:$J$766),"") | K9: =IFERROR(LOOKUP(2,1/('Weekly Tracker'!$E$2:$E$766=$A9)/('Weekly Tracker'!$N$2:$N$766<>""),'Weekly Tracker'!$N$2:$N$766),"") | L9: =IFERROR(LOOKUP(2,1/('Weekly Tracker'!$E$2:$E$766=$A9)/('Weekly Tracker'!$O$2:$O$766<>""),'Weekly Tracker'!$O$2:$O$766),"")
A10: Mani Kandan FB | B10: 971554780531, +971 55 478 0531 | F10: =IFERROR(LOOKUP(2,1/('Weekly Tracker'!$E$2:$E$766=$A10)/('Weekly Tracker'!$F$2:$F$766<>""),'Weekly Tracker'!$F$2:$F$766),"") | G10: =IF(F10<>"",LOOKUP(2,1/('Weekly Tracker'!$E$2:$E$766=$A10)/('Weekly Tracker'!$F$2:$F$766<>""),'Weekly Tracker'!$G$2:$G$766),"") | H10: =IFERROR(LOOKUP(2,1/('Weekly Tracker'!$E$2:$E$766=$A10)/('Weekly Tracker'!$H$2:$H$766<>""),'Weekly Tracker'!$H$2:$H$766),"") | I10: =IF(H10<>"",LOOKUP(2,1/('Weekly Tracker'!$E$2:$E$766=$A10)/('Weekly Tracker'!$H$2:$H$766<>""),'Weekly Tracker'!$I$2:$I$766),"") | J10: =IFERROR(LOOKUP(2,1/('Weekly Tracker'!$E$2:$E$766=$A10)/('Weekly Tracker'!$J$2:$J$766<>""),'Weekly Tracker'!$J$2:$J$766),"") | K10: =IFERROR(LOOKUP(2,1/('Weekly Tracker'!$E$2:$E$766=$A10)/('Weekly Tracker'!$N$2:$N$766<>""),'Weekly Tracker'!$N$2:$N$766),"") | L10: =IFERROR(LOOKUP(2,1/('Weekly Tracker'!$E$2:$E$766=$A10)/('Weekly Tracker'!$O$2:$O$766<>""),'Weekly Tracker'!$O$2:$O$766),"")
A11: Mani VJ FB | B11: 917904326199 | F11: =IFERROR(LOOKUP(2,1/('Weekly Tracker'!$E$2:$E$766=$A11)/('Weekly Tracker'!$F$2:$F$766<>""),'Weekly Tracker'!$F$2:$F$766),"") | G11: =IF(F11<>"",LOOKUP(2,1/('Weekly Tracker'!$E$2:$E$766=$A11)/('Weekly Tracker'!$F$2:$F$766<>""),'Weekly Tracker'!$G$2:$G$766),"") | H11: =IFERROR(LOOKUP(2,1/('Weekly Tracker'!$E$2:$E$766=$A11)/('Weekly Tracker'!$H$2:$H$766<>""),'Weekly Tracker'!$H$2:$H$766),"") | I11: =IF(H11<>"",LOOKUP(2,1/('Weekly Tracker'!$E$2:$E$766=$A11)/('Weekly Tracker'!$H$2:$H$766<>""),'Weekly Tracker'!$I$2:$I$766),"") | J11: =IFERROR(LOOKUP(2,1/('Weekly Tracker'!$E$2:$E$766=$A11)/('Weekly Tracker'!$J$2:$J$766<>""),'Weekly Tracker'!$J$2:$J$766),"") | K11: =IFERROR(LOOKUP(2,1/('Weekly Tracker'!$E$2:$E$766=$A11)/('Weekly Tracker'!$N$2:$N$766<>""),'Weekly Tracker'!$N$2:$N$766),"") | L11: =IFERROR(LOOKUP(2,1/('Weekly Tracker'!$E$2:$E$766=$A11)/('Weekly Tracker'!$O$2:$O$766<>""),'Weekly Tracker'!$O$2:$O$766),"")
A12: Niranjan Urja | F12: =IFERROR(LOOKUP(2,1/('Weekly Tracker'!$E$2:$E$766=$A12)/('Weekly Tracker'!$F$2:$F$766<>""),'Weekly Tracker'!$F$2:$F$766),"") | G12: =IF(F12<>"",LOOKUP(2,1/('Weekly Tracker'!$E$2:$E$766=$A12)/('Weekly Tracker'!$F$2:$F$766<>""),'Weekly Tracker'!$G$2:$G$766),"") | H12: =IFERROR(LOOKUP(2,1/('Weekly Tracker'!$E$2:$E$766=$A12)/('Weekly Tracker'!$H$2:$H$766<>""),'Weekly Tracker'!$H$2:$H$766),"") | I12: =IF(H12<>"",LOOKUP(2,1/('Weekly Tracker'!$E$2:$E$766=$A12)/('Weekly Tracker'!$H$2:$H$766<>""),'Weekly Tracker'!$I$2:$I$766),"") | J12: =IFERROR(LOOKUP(2,1/('Weekly Tracker'!$E$2:$E$766=$A12)/('Weekly Tracker'!$J$2:$J$766<>""),'Weekly Tracker'!$J$2:$J$766),"") | K12: =IFERROR(LOOKUP(2,1/('Weekly Tracker'!$E$2:$E$766=$A12)/('Weekly Tracker'!$N$2:$N$766<>""),'Weekly Tracker'!$N$2:$N$766),"") | L12: =IFERROR(LOOKUP(2,1/('Weekly Tracker'!$E$2:$E$766=$A12)/('Weekly Tracker'!$O$2:$O$766<>""),'Weekly Tracker'!$O$2:$O$766),"")
A13: Anbu Urja | B13: 917418262653 | F13: =IFERROR(LOOKUP(2,1/('Weekly Tracker'!$E$2:$E$766=$A13)/('Weekly Tracker'!$F$2:$F$766<>""),'Weekly Tracker'!$F$2:$F$766),"") | G13: =IF(F13<>"",LOOKUP(2,1/('Weekly Tracker'!$E$2:$E$766=$A13)/('Weekly Tracker'!$F$2:$F$766<>""),'Weekly Tracker'!$G$2:$G$766),"") | H13: =IFERROR(LOOKUP(2,1/('Weekly Tracker'!$E$2:$E$766=$A13)/('Weekly Tracker'!$H$2:$H$766<>""),'Weekly Tracker'!$H$2:$H$766),"") | I13: =IF(H13<>"",LOOKUP(2,1/('Weekly Tracker'!$E$2:$E$766=$A13)/('Weekly Tracker'!$H$2:$H$766<>""),'Weekly Tracker'!$I$2:$I$766),"") | J13: =IFERROR(LOOKUP(2,1/('Weekly Tracker'!$E$2:$E$766=$A13)/('Weekly Tracker'!$J$2:$J$766<>""),'Weekly Tracker'!$J$2:$J$766),"") | K13: =IFERROR(LOOKUP(2,1/('Weekly Tracker'!$E$2:$E$766=$A13)/('Weekly Tracker'!$N$2:$N$766<>""),'Weekly Tracker'!$N$2:$N$766),"") | L13: =IFERROR(LOOKUP(2,1/('Weekly Tracker'!$E$2:$E$766=$A13)/('Weekly Tracker'!$O$2:$O$766<>""),'Weekly Tracker'!$O$2:$O$766),"")
A14: Vinoth Kumar Mech | B14: 919099102966, +91 90991 02966, 919655485302 | F14: =IFERROR(LOOKUP(2,1/('Weekly Tracker'!$E$2:$E$766=$A14)/('Weekly Tracker'!$F$2:$F$766<>""),'Weekly Tracker'!$F$2:$F$766),"") | G14: =IF(F14<>"",LOOKUP(2,1/('Weekly Tracker'!$E$2:$E$766=$A14)/('Weekly Tracker'!$F$2:$F$766<>""),'Weekly Tracker'!$G$2:$G$766),"") | H14: =IFERROR(LOOKUP(2,1/('Weekly Tracker'!$E$2:$E$766=$A14)/('Weekly Tracker'!$H$2:$H$766<>""),'Weekly Tracker'!$H$2:$H$766),"") | I14: =IF(H14<>"",LOOKUP(2,1/('Weekly Tracker'!$E$2:$E$766=$A14)/('Weekly Tracker'!$H$2:$H$766<>""),'Weekly Tracker'!$I$2:$I$766),"") | J14: =IFERROR(LOOKUP(2,1/('Weekly Tracker'!$E$2:$E$766=$A14)/('Weekly Tracker'!$J$2:$J$766<>""),'Weekly Tracker'!$J$2:$J$766),"") | K14: =IFERROR(LOOKUP(2,1/('Weekly Tracker'!$E$2:$E$766=$A14)/('Weekly Tracker'!$N$2:$N$766<>""),'Weekly Tracker'!$N$2:$N$766),"") | L14: =IFERROR(LOOKUP(2,1/('Weekly Tracker'!$E$2:$E$766=$A14)/('Weekly Tracker'!$O$2:$O$766<>""),'Weekly Tracker'!$O$2:$O$766),"")
A15: Manikandan FB | B15: 7639748654, 9965410728, 99654 10728 | F15: =IFERROR(LOOKUP(2,1/('Weekly Tracker'!$E$2:$E$766=$A15)/('Weekly Tracker'!$F$2:$F$766<>""),'Weekly Tracker'!$F$2:$F$766),"") | G15: =IF(F15<>"",LOOKUP(2,1/('Weekly Tracker'!$E$2:$E$766=$A15)/('Weekly Tracker'!$F$2:$F$766<>""),'Weekly Tracker'!$G$2:$G$766),"") | H15: =IFERROR(LOOKUP(2,1/('Weekly Tracker'!$E$2:$E$766=$A15)/('Weekly Tracker'!$H$2:$H$766<>""),'Weekly Tracker'!$H$2:$H$766),"") | I15: =IF(H15<>"",LOOKUP(2,1/('Weekly Tracker'!$E$2:$E$766=$A15)/('Weekly Tracker'!$H$2:$H$766<>""),'Weekly Tracker'!$I$2:$I$766),"") | J15: =IFERROR(LOOKUP(2,1/('Weekly Tracker'!$E$2:$E$766=$A15)/('Weekly Tracker'!$J$2:$J$766<>""),'Weekly Tracker'!$J$2:$J$766),"") | K15: =IFERROR(LOOKUP(2,1/('Weekly Tracker'!$E$2:$E$766=$A15)/('Weekly Tracker'!$N$2:$N$766<>""),'Weekly Tracker'!$N$2:$N$766),"") | L15: =IFERROR(LOOKUP(2,1/('Weekly Tracker'!$E$2:$E$766=$A15)/('Weekly Tracker'!$O$2:$O$766<>""),'Weekly Tracker'!$O$2:$O$766),"")
A16: Urjanet | F16: =IFERROR(LOOKUP(2,1/('Weekly Tracker'!$E$2:$E$766=$A16)/('Weekly Tracker'!$F$2:$F$766<>""),'Weekly Tracker'!$F$2:$F$766),"") | G16: =IF(F16<>"",LOOKUP(2,1/('Weekly Tracker'!$E$2:$E$766=$A16)/('Weekly Tracker'!$F$2:$F$766<>""),'Weekly Tracker'!$G$2:$G$766),"") | H16: =IFERROR(LOOKUP(2,1/('Weekly Tracker'!$E$2:$E$766=$A16)/('Weekly Tracker'!$H$2:$H$766<>""),'Weekly Tracker'!$H$2:$H$766),"") | I16: =IF(H16<>"",LOOKUP(2,1/('Weekly Tracker'!$E$2:$E$766=$A16)/('Weekly Tracker'!$H$2:$H$766<>""),'Weekly Tracker'!$I$2:$I$766),"") | J16: =IFERROR(LOOKUP(2,1/('Weekly Tracker'!$E$2:$E$766=$A16)/('Weekly Tracker'!$J$2:$J$766<>""),'Weekly Tracker'!$J$2:$J$766),"") | K16: =IFERROR(LOOKUP(2,1/('Weekly Tracker'!$E$2:$E$766=$A16)/('Weekly Tracker'!$N$2:$N$766<>""),'Weekly Tracker'!$N$2:$N$766),"") | L16: =IFERROR(LOOKUP(2,1/('Weekly Tracker'!$E$2:$E$766=$A16)/('Weekly Tracker'!$O$2:$O$766<>""),'Weekly Tracker'!$O$2:$O$766),"")
A17: Verizon | F17: =IFERROR(LOOKUP(2,1/('Weekly Tracker'!$E$2:$E$766=$A17)/('Weekly Tracker'!$F$2:$F$766<>""),'Weekly Tracker'!$F$2:$F$766),"") | G17: =IF(F17<>"",LOOKUP(2,1/('Weekly Tracker'!$E$2:$E$766=$A17)/('Weekly Tracker'!$F$2:$F$766<>""),'Weekly Tracker'!$G$2:$G$766),"") | H17: =IFERROR(LOOKUP(2,1/('Weekly Tracker'!$E$2:$E$766=$A17)/('Weekly Tracker'!$H$2:$H$766<>""),'Weekly Tracker'!$H$2:$H$766),"") | I17: =IF(H17<>"",LOOKUP(2,1/('Weekly Tracker'!$E$2:$E$766=$A17)/('Weekly Tracker'!$H$2:$H$766<>""),'Weekly Tracker'!$I$2:$I$766),"") | J17: =IFERROR(LOOKUP(2,1/('Weekly Tracker'!$E$2:$E$766=$A17)/('Weekly Tracker'!$J$2:$J$766<>""),'Weekly Tracker'!$J$2:$J$766),"") | K17: =IFERROR(LOOKUP(2,1/('Weekly Tracker'!$E$2:$E$766=$A17)/('Weekly Tracker'!$N$2:$N$766<>""),'Weekly Tracker'!$N$2:$N$766),"") | L17: =IFERROR(LOOKUP(2,1/('Weekly Tracker'!$E$2:$E$766=$A17)/('Weekly Tracker'!$O$2:$O$766<>""),'Weekly Tracker'!$O$2:$O$766),"")
A18: School | F18: =IFERROR(LOOKUP(2,1/('Weekly Tracker'!$E$2:$E$766=$A18)/('Weekly Tracker'!$F$2:$F$766<>""),'Weekly Tracker'!$F$2:$F$766),"") | G18: =IF(F18<>"",LOOKUP(2,1/('Weekly Tracker'!$E$2:$E$766=$A18)/('Weekly Tracker'!$F$2:$F$766<>""),'Weekly Tracker'!$G$2:$G$766),"") | H18: =IFERROR(LOOKUP(2,1/('Weekly Tracker'!$E$2:$E$766=$A18)/('Weekly Tracker'!$H$2:$H$766<>""),'Weekly Tracker'!$H$2:$H$766),"") | I18: =IF(H18<>"",LOOKUP(2,1/('Weekly Tracker'!$E$2:$E$766=$A18)/('Weekly Tracker'!$H$2:$H$766<>""),'Weekly Tracker'!$I$2:$I$766),"") | J18: =IFERROR(LOOKUP(2,1/('Weekly Tracker'!$E$2:$E$766=$A18)/('Weekly Tracker'!$J$2:$J$766<>""),'Weekly Tracker'!$J$2:$J$766),"") | K18: =IFERROR(LOOKUP(2,1/('Weekly Tracker'!$E$2:$E$766=$A18)/('Weekly Tracker'!$N$2:$N$766<>""),'Weekly Tracker'!$N$2:$N$766),"") | L18: =IFERROR(LOOKUP(2,1/('Weekly Tracker'!$E$2:$E$766=$A18)/('Weekly Tracker'!$O$2:$O$766<>""),'Weekly Tracker'!$O$2:$O$766),"")
A19: Mathan Kumar FB | B19: 6380108044, 9092455151, 90924 55151 | F19: =IFERROR(LOOKUP(2,1/('Weekly Tracker'!$E$2:$E$766=$A19)/('Weekly Tracker'!$F$2:$F$766<>""),'Weekly Tracker'!$F$2:$F$766),"") | G19: =IF(F19<>"",LOOKUP(2,1/('Weekly Tracker'!$E$2:$E$766=$A19)/('Weekly Tracker'!$F$2:$F$766<>""),'Weekly Tracker'!$G$2:$G$766),"") | H19: =IFERROR(LOOKUP(2,1/('Weekly Tracker'!$E$2:$E$766=$A19)/('Weekly Tracker'!$H$2:$H$766<>""),'Weekly Tracker'!$H$2:$H$766),"") | I19: =IF(H19<>"",LOOKUP(2,1/('Weekly Tracker'!$E$2:$E$766=$A19)/('Weekly Tracker'!$H$2:$H$766<>""),'Weekly Tracker'!$I$2:$I$766),"") | J19: =IFERROR(LOOKUP(2,1/('Weekly Tracker'!$E$2:$E$766=$A19)/('Weekly Tracker'!$J$2:$J$766<>""),'Weekly Tracker'!$J$2:$J$766),"") | K19: =IFERROR(LOOKUP(2,1/('Weekly Tracker'!$E$2:$E$766=$A19)/('Weekly Tracker'!$N$2:$N$766<>""),'Weekly Tracker'!$N$2:$N$766),"") | L19: =IFERROR(LOOKUP(2,1/('Weekly Tracker'!$E$2:$E$766=$A19)/('Weekly Tracker'!$O$2:$O$766<>""),'Weekly Tracker'!$O$2:$O$766),"")
A20: Mani Jaikrish FB | B20: 919206477402, +91 92064 77402 | F20: =IFERROR(LOOKUP(2,1/('Weekly Tracker'!$E$2:$E$766=$A20)/('Weekly Tracker'!$F$2:$F$766<>""),'Weekly Tracker'!$F$2:$F$766),"") | G20: =IF(F20<>"",LOOKUP(2,1/('Weekly Tracker'!$E$2:$E$766=$A20)/('Weekly Tracker'!$F$2:$F$766<>""),'Weekly Tracker'!$G$2:$G$766),"") | H20: =IFERROR(LOOKUP(2,1/('Weekly Tracker'!$E$2:$E$766=$A20)/('Weekly Tracker'!$H$2:$H$766<>""),'Weekly Tracker'!$H$2:$H$766),"") | I20: =IF(H20<>"",LOOKUP(2,1/('Weekly Tracker'!$E$2:$E$766=$A20)/('Weekly Tracker'!$H$2:$H$766<>""),'Weekly Tracker'!$I$2:$I$766),"") | J20: =IFERROR(LOOKUP(2,1/('Weekly Tracker'!$E$2:$E$766=$A20)/('Weekly Tracker'!$J$2:$J$766<>""),'Weekly Tracker'!$J$2:$J$766),"") | K20: =IFERROR(LOOKUP(2,1/('Weekly Tracker'!$E$2:$E$766=$A20)/('Weekly Tracker'!$N$2:$N$766<>""),'Weekly Tracker'!$N$2:$N$766),"") | L20: =IFERROR(LOOKUP(2,1/('Weekly Tracker'!$E$2:$E$766=$A20)/('Weekly Tracker'!$O$2:$O$766<>""),'Weekly Tracker'!$O$2:$O$766),"")
A21: Ajith Kumar Grp Ucen | B21: 917402769024 | F21: =IFERROR(LOOKUP(2,1/('Weekly Tracker'!$E$2:$E$766=$A21)/('Weekly Tracker'!$F$2:$F$766<>""),'Weekly Tracker'!$F$2:$F$766),"") | G21: =IF(F21<>"",LOOKUP(2,1/('Weekly Tracker'!$E$2:$E$766=$A21)/('Weekly Tracker'!$F$2:$F$766<>""),'Weekly Tracker'!$G$2:$G$766),"") | H21: =IFERROR(LOOKUP(2,1/('Weekly Tracker'!$E$2:$E$766=$A21)/('Weekly Tracker'!$H$2:$H$766<>""),'Weekly Tracker'!$H$2:$H$766),"") | I21: =IF(H21<>"",LOOKUP(2,1/('Weekly Tracker'!$E$2:$E$766=$A21)/('Weekly Tracker'!$H$2:$H$766<>""),'Weekly Tracker'!$I$2:$I$766),"") | J21: =IFERROR(LOOKUP(2,1/('Weekly Tracker'!$E$2:$E$766=$A21)/('Weekly Tracker'!$J$2:$J$766<>""),'Weekly Tracker'!$J$2:$J$766),"") | K21: =IFERROR(LOOKUP(2,1/('Weekly Tracker'!$E$2:$E$766=$A21)/('Weekly Tracker'!$N$2:$N$766<>""),'Weekly Tracker'!$N$2:$N$766),"") | L21: =IFERROR(LOOKUP(2,1/('Weekly Tracker'!$E$2:$E$766=$A21)/('Weekly Tracker'!$O$2:$O$766<>""),'Weekly Tracker'!$O$2:$O$766),"")
A22: VP VenkadeshaPerumal | B22: 8807791011 | F22: =IFERROR(LOOKUP(2,1/('Weekly Tracker'!$E$2:$E$766=$A22)/('Weekly Tracker'!$F$2:$F$766<>""),'Weekly Tracker'!$F$2:$F$766),"") | G22: =IF(F22<>"",LOOKUP(2,1/('Weekly Tracker'!$E$2:$E$766=$A22)/('Weekly Tracker'!$F$2:$F$766<>""),'Weekly Tracker'!$G$2:$G$766),"") | H22: =IFERROR(LOOKUP(2,1/('Weekly Tracker'!$E$2:$E$766=$A22)/('Weekly Tracker'!$H$2:$H$766<>""),'Weekly Tracker'!$H$2:$H$766),"") | I22: =IF(H22<>"",LOOKUP(2,1/('Weekly Tracker'!$E$2:$E$766=$A22)/('Weekly Tracker'!$H$2:$H$766<>""),'Weekly Tracker'!$I$2:$I$766),"") | J22: =IFERROR(LOOKUP(2,1/('Weekly Tracker'!$E$2:$E$766=$A22)/('Weekly Tracker'!$J$2:$J$766<>""),'Weekly Tracker'!$J$2:$J$766),"") | K22: =IFERROR(LOOKUP(2,1/('Weekly Tracker'!$E$2:$E$766=$A22)/('Weekly Tracker'!$N$2:$N$766<>""),'Weekly Tracker'!$N$2:$N$766),"") | L22: =IFERROR(LOOKUP(2,1/('Weekly Tracker'!$E$2:$E$766=$A22)/('Weekly Tracker'!$O$2:$O$766<>""),'Weekly Tracker'!$O$2:$O$766),"")
A23: Rakesh TL Urja | B23: 919791063268 | F23: =IFERROR(LOOKUP(2,1/('Weekly Tracker'!$E$2:$E$766=$A23)/('Weekly Tracker'!$F$2:$F$766<>""),'Weekly Tracker'!$F$2:$F$766),"") | G23: =IF(F23<>"",LOOKUP(2,1/('Weekly Tracker'!$E$2:$E$766=$A23)/('Weekly Tracker'!$F$2:$F$766<>""),'Weekly Tracker'!$G$2:$G$766),"") | H23: =IFERROR(LOOKUP(2,1/('Weekly Tracker'!$E$2:$E$766=$A23)/('Weekly Tracker'!$H$2:$H$766<>""),'Weekly Tracker'!$H$2:$H$766),"") | I23: =IF(H23<>"",LOOKUP(2,1/('Weekly Tracker'!$E$2:$E$766=$A23)/('Weekly Tracker'!$H$2:$H$766<>""),'Weekly Tracker'!$I$2:$I$766),"") | J23: =IFERROR(LOOKUP(2,1/('Weekly Tracker'!$E$2:$E$766=$A23)/('Weekly Tracker'!$J$2:$J$766<>""),'Weekly Tracker'!$J$2:$J$766),"") | K23: =IFERROR(LOOKUP(2,1/('Weekly Tracker'!$E$2:$E$766=$A23)/('Weekly Tracker'!$N$2:$N$766<>""),'Weekly Tracker'!$N$2:$N$766),"") | L23: =IFERROR(LOOKUP(2,1/('Weekly Tracker'!$E$2:$E$766=$A23)/('Weekly Tracker'!$O$2:$O$766<>""),'Weekly Tracker'!$O$2:$O$766),"")
A24: Anbu Arasan Urja | B24: 917418262653, 919626452984 | F24: =IFERROR(LOOKUP(2,1/('Weekly Tracker'!$E$2:$E$766=$A24)/('Weekly Tracker'!$F$2:$F$766<>""),'Weekly Tracker'!$F$2:$F$766),"") | G24: =IF(F24<>"",LOOKUP(2,1/('Weekly Tracker'!$E$2:$E$766=$A24)/('Weekly Tracker'!$F$2:$F$766<>""),'Weekly Tracker'!$G$2:$G$766),"") | H24: =IFERROR(LOOKUP(2,1/('Weekly Tracker'!$E$2:$E$766=$A24)/('Weekly Tracker'!$H$2:$H$766<>""),'Weekly Tracker'!$H$2:$H$766),"") | I24: =IF(H24<>"",LOOKUP(2,1/('Weekly Tracker'!$E$2:$E$766=$A24)/('Weekly Tracker'!$H$2:$H$766<>""),'Weekly Tracker'!$I$2:$I$766),"") | J24: =IFERROR(LOOKUP(2,1/('Weekly Tracker'!$E$2:$E$766=$A24)/('Weekly Tracker'!$J$2:$J$766<>""),'Weekly Tracker'!$J$2:$J$766),"") | K24: =IFERROR(LOOKUP(2,1/('Weekly Tracker'!$E$2:$E$766=$A24)/('Weekly Tracker'!$N$2:$N$766<>""),'Weekly Tracker'!$N$2:$N$766),"") | L24: =IFERROR(LOOKUP(2,1/('Weekly Tracker'!$E$2:$E$766=$A24)/('Weekly Tracker'!$O$2:$O$766<>""),'Weekly Tracker'!$O$2:$O$766),"")
A25: Suresh Dada FB | B25: 919489801803 | F25: =IFERROR(LOOKUP(2,1/('Weekly Tracker'!$E$2:$E$766=$A25)/('Weekly Tracker'!$F$2:$F$766<>""),'Weekly Tracker'!$F$2:$F$766),"") | G25: =IF(F25<>"",LOOKUP(2,1/('Weekly Tracker'!$E$2:$E$766=$A25)/('Weekly Tracker'!$F$2:$F$766<>""),'Weekly Tracker'!$G$2:$G$766),"") | H25: =IFERROR(LOOKUP(2,1/('Weekly Tracker'!$E$2:$E$766=$A25)/('Weekly Tracker'!$H$2:$H$766<>""),'Weekly Tracker'!$H$2:$H$766),"") | I25: =IF(H25<>"",LOOKUP(2,1/('Weekly Tracker'!$E$2:$E$766=$A25)/('Weekly Tracker'!$H$2:$H$766<>""),'Weekly Tracker'!$I$2:$I$766),"") | J25: =IFERROR(LOOKUP(2,1/('Weekly Tracker'!$E$2:$E$766=$A25)/('Weekly Tracker'!$J$2:$J$766<>""),'Weekly Tracker'!$J$2:$J$766),"") | K25: =IFERROR(LOOKUP(2,1/('Weekly Tracker'!$E$2:$E$766=$A25)/('Weekly Tracker'!$N$2:$N$766<>""),'Weekly Tracker'!$N$2:$N$766),"") | L25: =IFERROR(LOOKUP(2,1/('Weekly Tracker'!$E$2:$E$766=$A25)/('Weekly Tracker'!$O$2:$O$766<>""),'Weekly Tracker'!$O$2:$O$766),"")
A26: Bala Murugan FB | B26: 9486622065, 7598704205, +91 91762 46373, 94866 22065 | F26: =IFERROR(LOOKUP(2,1/('Weekly Tracker'!$E$2:$E$766=$A26)/('Weekly Tracker'!$F$2:$F$766<>""),'Weekly Tracker'!$F$2:$F$766),"") | G26: =IF(F26<>"",LOOKUP(2,1/('Weekly Tracker'!$E$2:$E$766=$A26)/('Weekly Tracker'!$F$2:$F$766<>""),'Weekly Tracker'!$G$2:$G$766),"") | H26: =IFERROR(LOOKUP(2,1/('Weekly Tracker'!$E$2:$E$766=$A26)/('Weekly Tracker'!$H$2:$H$766<>""),'Weekly Tracker'!$H$2:$H$766),"") | I26: =IF(H26<>"",LOOKUP(2,1/('Weekly Tracker'!$E$2:$E$766=$A26)/('Weekly Tracker'!$H$2:$H$766<>""),'Weekly Tracker'!$I$2:$I$766),"") | J26: =IFERROR(LOOKUP(2,1/('Weekly Tracker'!$E$2:$E$766=$A26)/('Weekly Tracker'!$J$2:$J$766<>""),'Weekly Tracker'!$J$2:$J$766),"") | K26: =IFERROR(LOOKUP(2,1/('Weekly Tracker'!$E$2:$E$766=$A26)/('Weekly Tracker'!$N$2:$N$766<>""),'Weekly Tracker'!$N$2:$N$766),"") | L26: =IFERROR(LOOKUP(2,1/('Weekly Tracker'!$E$2:$E$766=$A26)/('Weekly Tracker'!$O$2:$O$766<>""),'Weekly Tracker'!$O$2:$O$766),"")
A27: Rajesh Sekar FB | B27: 917639239885, +91 76392 39885 | F27: =IFERROR(LOOKUP(2,1/('Weekly Tracker'!$E$2:$E$766=$A27)/('Weekly Tracker'!$F$2:$F$766<>""),'Weekly Tracker'!$F$2:$F$766),"") | G27: =IF(F27<>"",LOOKUP(2,1/('Weekly Tracker'!$E$2:$E$766=$A27)/('Weekly Tracker'!$F$2:$F$766<>""),'Weekly Tracker'!$G$2:$G$766),"") | H27: =IFERROR(LOOKUP(2,1/('Weekly Tracker'!$E$2:$E$766=$A27)/('Weekly Tracker'!$H$2:$H$766<>""),'Weekly Tracker'!$H$2:$H$766),"") | I27: =IF(H27<>"",LOOKUP(2,1/('Weekly Tracker'!$E$2:$E$766=$A27)/('Weekly Tracker'!$H$2:$H$766<>""),'Weekly Tracker'!$I$2:$I$766),"") | J27: =IFERROR(LOOKUP(2,1/('Weekly Tracker'!$E$2:$E$766=$A27)/('Weekly Tracker'!$J$2:$J$766<>""),'Weekly Tracker'!$J$2:$J$766),"") | K27: =IFERROR(LOOKUP(2,1/('Weekly Tracker'!$E$2:$E$766=$A27)/('Weekly Tracker'!$N$2:$N$766<>""),'Weekly Tracker'!$N$2:$N$766),"") | L27: =IFERROR(LOOKUP(2,1/('Weekly Tracker'!$E$2:$E$766=$A27)/('Weekly Tracker'!$O$2:$O$766<>""),'Weekly Tracker'!$O$2:$O$766),"")
A28: Sai Adithya FB | B28: 917358758870 | F28: =IFERROR(LOOKUP(2,1/('Weekly Tracker'!$E$2:$E$766=$A28)/('Weekly Tracker'!$F$2:$F$766<>""),'Weekly Tracker'!$F$2:$F$766),"") | G28: =IF(F28<>"",LOOKUP(2,1/('Weekly Tracker'!$E$2:$E$766=$A28)/('Weekly Tracker'!$F$2:$F$766<>""),'Weekly Tracker'!$G$2:$G$766),"") | H28: =IFERROR(LOOKUP(2,1/('Weekly Tracker'!$E$2:$E$766=$A28)/('Weekly Tracker'!$H$2:$H$766<>""),'Weekly Tracker'!$H$2:$H$766),"") | I28: =IF(H28<>"",LOOKUP(2,1/('Weekly Tracker'!$E$2:$E$766=$A28)/('Weekly Tracker'!$H$2:$H$766<>""),'Weekly Tracker'!$I$2:$I$766),"") | J28: =IFERROR(LOOKUP(2,1/('Weekly Tracker'!$E$2:$E$766=$A28)/('Weekly Tracker'!$J$2:$J$766<>""),'Weekly Tracker'!$J$2:$J$766),"") | K28: =IFERROR(LOOKUP(2,1/('Weekly Tracker'!$E$2:$E$766=$A28)/('Weekly Tracker'!$N$2:$N$766<>""),'Weekly Tracker'!$N$2:$N$766),"") | L28: =IFERROR(LOOKUP(2,1/('Weekly Tracker'!$E$2:$E$766=$A28)/('Weekly Tracker'!$O$2:$O$766<>""),'Weekly Tracker'!$O$2:$O$766),"")
A29: Niranjan Past Urja | B29: 918939230269 | F29: =IFERROR(LOOKUP(2,1/('Weekly Tracker'!$E$2:$E$766=$A29)/('Weekly Tracker'!$F$2:$F$766<>""),'Weekly Tracker'!$F$2:$F$766),"") | G29: =IF(F29<>"",LOOKUP(2,1/('Weekly Tracker'!$E$2:$E$766=$A29)/('Weekly Tracker'!$F$2:$F$766<>""),'Weekly Tracker'!$G$2:$G$766),"") | H29: =IFERROR(LOOKUP(2,1/('Weekly Tracker'!$E$2:$E$766=$A29)/('Weekly Tracker'!$H$2:$H$766<>""),'Weekly Tracker'!$H$2:$H$766),"") | I29: =IF(H29<>"",LOOKUP(2,1/('Weekly Tracker'!$E$2:$E$766=$A29)/('Weekly Tracker'!$H$2:$H$766<>""),'Weekly Tracker'!$I$2:$I$766),"") | J29: =IFERROR(LOOKUP(2,1/('Weekly Tracker'!$E$2:$E$766=$A29)/('Weekly Tracker'!$J$2:$J$766<>""),'Weekly Tracker'!$J$2:$J$766),"") | K29: =IFERROR(LOOKUP(2,1/('Weekly Tracker'!$E$2:$E$766=$A29)/('Weekly Tracker'!$N$2:$N$766<>""),'Weekly Tracker'!$N$2:$N$766),"") | L29: =IFERROR(LOOKUP(2,1/('Weekly Tracker'!$E$2:$E$766=$A29)/('Weekly Tracker'!$O$2:$O$766<>""),'Weekly Tracker'!$O$2:$O$766),"")
A30: Ajith Kumar Grp UCEN | B30: 919655944652 | F30: =IFERROR(LOOKUP(2,1/('Weekly Tracker'!$E$2:$E$766=$A30)/('Weekly Tracker'!$F$2:$F$766<>""),'Weekly Tracker'!$F$2:$F$766),"") | G30: =IF(F30<>"",LOOKUP(2,1/('Weekly Tracker'!$E$2:$E$766=$A30)/('Weekly Tracker'!$F$2:$F$766<>""),'Weekly Tracker'!$G$2:$G$766),"") | H30: =IFERROR(LOOKUP(2,1/('Weekly Tracker'!$E$2:$E$766=$A30)/('Weekly Tracker'!$H$2:$H$766<>""),'Weekly Tracker'!$H$2:$H$766),"") | I30: =IF(H30<>"",LOOKUP(2,1/('Weekly Tracker'!$E$2:$E$766=$A30)/('Weekly Tracker'!$H$2:$H$766<>""),'Weekly Tracker'!$I$2:$I$766),"") | J30: =IFERROR(LOOKUP(2,1/('Weekly Tracker'!$E$2:$E$766=$A30)/('Weekly Tracker'!$J$2:$J$766<>""),'Weekly Tracker'!$J$2:$J$766),"") | K30: =IFERROR(LOOKUP(2,1/('Weekly Tracker'!$E$2:$E$766=$A30)/('Weekly Tracker'!$N$2:$N$766<>""),'Weekly Tracker'!$N$2:$N$766),"") | L30: =IFERROR(LOOKUP(2,1/('Weekly Tracker'!$E$2:$E$766=$A30)/('Weekly Tracker'!$O$2:$O$766<>""),'Weekly Tracker'!$O$2:$O$766),"")
... A138: Ajin (Nishanth) | B138: 919791370484 | F138: =IFERROR(LOOKUP(2,1/('Weekly Tracker'!$E$2:$E$766=$A138)/('Weekly Tracker'!$F$2:$F$766<>""),'Weekly Tracker'!$F$2:$F$766),"") | G138: =IF(F138<>"",LOOKUP(2,1/('Weekly Tracker'!$E$2:$E$766=$A138)/('Weekly Tracker'!$F$2:$F$766<>""),'Weekly Tracker'!$G$2:$G$766),"") | H138: =IFERROR(LOOKUP(2,1/('Weekly Tracker'!$E$2:$E$766=$A138)/('Weekly Tracker'!$H$2:$H$766<>""),'Weekly Tracker'!$H$2:$H$766),"") | I138: =IF(H138<>"",LOOKUP(2,1/('Weekly Tracker'!$E$2:$E$766=$A138)/('Weekly Tracker'!$H$2:$H$766<>""),'Weekly Tracker'!$I$2:$I$766),"") | J138: =IFERROR(LOOKUP(2,1/('Weekly Tracker'!$E$2:$E$766=$A138)/('Weekly Tracker'!$J$2:$J$766<>""),'Weekly Tracker'!$J$2:$J$766),"") | K138: =IFERROR(LOOKUP(2,1/('Weekly Tracker'!$E$2:$E$766=$A138)/('Weekly Tracker'!$N$2:$N$766<>""),'Weekly Tracker'!$N$2:$N$766),"") | L138: =IFERROR(LOOKUP(2,1/('Weekly Tracker'!$E$2:$E$766=$A138)/('Weekly Tracker'!$O$2:$O$766<>""),'Weekly Tracker'!$O$2:$O$766),"")
A139: Abijith Uday Infy | B139: +91 95001 24191 | E139: Tamil Nadu, India | F139: =IFERROR(LOOKUP(2,1/('Weekly Tracker'!$E$2:$E$766=$A139)/('Weekly Tracker'!$F$2:$F$766<>""),'Weekly Tracker'!$F$2:$F$766),"") | G139: =IF(F139<>"",LOOKUP(2,1/('Weekly Tracker'!$E$2:$E$766=$A139)/('Weekly Tracker'!$F$2:$F$766<>""),'Weekly Tracker'!$G$2:$G$766),"") | H139: =IFERROR(LOOKUP(2,1/('Weekly Tracker'!$E$2:$E$766=$A139)/('Weekly Tracker'!$H$2:$H$766<>""),'Weekly Tracker'!$H$2:$H$766),"") | I139: =IF(H139<>"",LOOKUP(2,1/('Weekly Tracker'!$E$2:$E$766=$A139)/('Weekly Tracker'!$H$2:$H$766<>""),'Weekly Tracker'!$I$2:$I$766),"") | J139: =IFERROR(LOOKUP(2,1/('Weekly Tracker'!$E$2:$E$766=$A139)/('Weekly Tracker'!$J$2:$J$766<>""),'Weekly Tracker'!$J$2:$J$766),"") | K139: =IFERROR(LOOKUP(2,1/('Weekly Tracker'!$E$2:$E$766=$A139)/('Weekly Tracker'!$N$2:$N$766<>""),'Weekly Tracker'!$N$2:$N$766),"") | L139: =IFERROR(LOOKUP(2,1/('Weekly Tracker'!$E$2:$E$766=$A139)/('Weekly Tracker'!$O$2:$O$766<>""),'Weekly Tracker'!$O$2:$O$766),"")
A140: Shibi Chakravarthy FB | B140: 919566612326 | F140: =IFERROR(LOOKUP(2,1/('Weekly Tracker'!$E$2:$E$766=$A140)/('Weekly Tracker'!$F$2:$F$766<>""),'Weekly Tracker'!$F$2:$F$766),"") | G140: =IF(F140<>"",LOOKUP(2,1/('Weekly Tracker'!$E$2:$E$766=$A140)/('Weekly Tracker'!$F$2:$F$766<>""),'Weekly Tracker'!$G$2:$G$766),"") | H140: =IFERROR(LOOKUP(2,1/('Weekly Tracker'!$E$2:$E$766=$A140)/('Weekly Tracker'!$H$2:$H$766<>""),'Weekly Tracker'!$H$2:$H$766),"") | I140: =IF(H140<>"",LOOKUP(2,1/('Weekly Tracker'!$E$2:$E$766=$A140)/('Weekly Tracker'!$H$2:$H$766<>""),'Weekly Tracker'!$I$2:$I$766),"") | J140: =IFERROR(LOOKUP(2,1/('Weekly Tracker'!$E$2:$E$766=$A140)/('Weekly Tracker'!$J$2:$J$766<>""),'Weekly Tracker'!$J$2:$J$766),"") | K140: =IFERROR(LOOKUP(2,1/('Weekly Tracker'!$E$2:$E$766=$A140)/('Weekly Tracker'!$N$2:$N$766<>""),'Weekly Tracker'!$N$2:$N$766),"") | L140: =IFERROR(LOOKUP(2,1/('Weekly Tracker'!$E$2:$E$766=$A140)/('Weekly Tracker'!$O$2:$O$766<>""),'Weekly Tracker'!$O$2:$O$766),"")
A141: Distress Number | B141: 112 | F141: =IFERROR(LOOKUP(2,1/('Weekly Tracker'!$E$2:$E$766=$A141)/('Weekly Tracker'!$F$2:$F$766<>""),'Weekly Tracker'!$F$2:$F$766),"") | G141: =IF(F141<>"",LOOKUP(2,1/('Weekly Tracker'!$E$2:$E$766=$A141)/('Weekly Tracker'!$F$2:$F$766<>""),'Weekly Tracker'!$G$2:$G$766),"") | H141: =IFERROR(LOOKUP(2,1/('Weekly Tracker'!$E$2:$E$766=$A141)/('Weekly Tracker'!$H$2:$H$766<>""),'Weekly Tracker'!$H$2:$H$766),"") | I141: =IF(H141<>"",LOOKUP(2,1/('Weekly Tracker'!$E$2:$E$766=$A141)/('Weekly Tracker'!$H$2:$H$766<>""),'Weekly Tracker'!$I$2:$I$766),"") | J141: =IFERROR(LOOKUP(2,1/('Weekly Tracker'!$E$2:$E$766=$A141)/('Weekly Tracker'!$J$2:$J$766<>""),'Weekly Tracker'!$J$2:$J$766),"") | K141: =IFERROR(LOOKUP(2,1/('Weekly Tracker'!$E$2:$E$766=$A141)/('Weekly Tracker'!$N$2:$N$766<>""),'Weekly Tracker'!$N$2:$N$766),"") | L141: =IFERROR(LOOKUP(2,1/('Weekly Tracker'!$E$2:$E$766=$A141)/('Weekly Tracker'!$O$2:$O$766<>""),'Weekly Tracker'!$O$2:$O$766),"")
A142: Padma Akka | B142: 919750383402 | E142: Tamil Nadu, India | F142: =IFERROR(LOOKUP(2,1/('Weekly Tracker'!$E$2:$E$766=$A142)/('Weekly Tracker'!$F$2:$F$766<>""),'Weekly Tracker'!$F$2:$F$766),"") | G142: =IF(F142<>"",LOOKUP(2,1/('Weekly Tracker'!$E$2:$E$766=$A142)/('Weekly Tracker'!$F$2:$F$766<>""),'Weekly Tracker'!$G$2:$G$766),"") | H142: =IFERROR(LOOKUP(2,1/('Weekly Tracker'!$E$2:$E$766=$A142)/('Weekly Tracker'!$H$2:$H$766<>""),'Weekly Tracker'!$H$2:$H$766),"") | I142: =IF(H142<>"",LOOKUP(2,1/('Weekly Tracker'!$E$2:$E$766=$A142)/('Weekly Tracker'!$H$2:$H$766<>""),'Weekly Tracker'!$I$2:$I$766),"") | J142: =IFERROR(LOOKUP(2,1/('Weekly Tracker'!$E$2:$E$766=$A142)/('Weekly Tracker'!$J$2:$J$766<>""),'Weekly Tracker'!$J$2:$J$766),"") | K142: =IFERROR(LOOKUP(2,1/('Weekly Tracker'!$E$2:$E$766=$A142)/('Weekly Tracker'!$N$2:$N$766<>""),'Weekly Tracker'!$N$2:$N$766),"") | L142: =IFERROR(LOOKUP(2,1/('Weekly Tracker'!$E$2:$E$766=$A142)/('Weekly Tracker'!$O$2:$O$766<>""),'Weekly Tracker'!$O$2:$O$766),"")
A143: Abhinav Krishna HCL | B143: 8920244428 | F143: =IFERROR(LOOKUP(2,1/('Weekly Tracker'!$E$2:$E$766=$A143)/('Weekly Tracker'!$F$2:$F$766<>""),'Weekly Tracker'!$F$2:$F$766),"") | G143: =IF(F143<>"",LOOKUP(2,1/('Weekly Tracker'!$E$2:$E$766=$A143)/('Weekly Tracker'!$F$2:$F$766<>""),'Weekly Tracker'!$G$2:$G$766),"") | H143: =IFERROR(LOOKUP(2,1/('Weekly Tracker'!$E$2:$E$766=$A143)/('Weekly Tracker'!$H$2:$H$766<>""),'Weekly Tracker'!$H$2:$H$766),"") | I143: =IF(H143<>"",LOOKUP(2,1/('Weekly Tracker'!$E$2:$E$766=$A143)/('Weekly Tracker'!$H$2:$H$766<>""),'Weekly Tracker'!$I$2:$I$766),"") | J143: =IFERROR(LOOKUP(2,1/('Weekly Tracker'!$E$2:$E$766=$A143)/('Weekly Tracker'!$J$2:$J$766<>""),'Weekly Tracker'!$J$2:$J$766),"") | K143: =IFERROR(LOOKUP(2,1/('Weekly Tracker'!$E$2:$E$766=$A143)/('Weekly Tracker'!$N$2:$N$766<>""),'Weekly Tracker'!$N$2:$N$766),"") | L143: =IFERROR(LOOKUP(2,1/('Weekly Tracker'!$E$2:$E$766=$A143)/('Weekly Tracker'!$O$2:$O$766<>""),'Weekly Tracker'!$O$2:$O$766),"")
A144: Tamil Puli Ford | B144: 919003888430 | F144: =IFERROR(LOOKUP(2,1/('Weekly Tracker'!$E$2:$E$766=$A144)/('Weekly Tracker'!$F$2:$F$766<>""),'Weekly Tracker'!$F$2:$F$766),"") | G144: =IF(F144<>"",LOOKUP(2,1/('Weekly Tracker'!$E$2:$E$766=$A144)/('Weekly Tracker'!$F$2:$F$766<>""),'Weekly Tracker'!$G$2:$G$766),"") | H144: =IFERROR(LOOKUP(2,1/('Weekly Tracker'!$E$2:$E$766=$A144)/('Weekly Tracker'!$H$2:$H$766<>""),'Weekly Tracker'!$H$2:$H$766),"") | I144: =IF(H144<>"",LOOKUP(2,1/('Weekly Tracker'!$E$2:$E$766=$A144)/('Weekly Tracker'!$H$2:$H$766<>""),'Weekly Tracker'!$I$2:$I$766),"") | J144: =IFERROR(LOOKUP(2,1/('Weekly Tracker'!$E$2:$E$766=$A144)/('Weekly Tracker'!$J$2:$J$766<>""),'Weekly Tracker'!$J$2:$J$766),"") | K144: =IFERROR(LOOKUP(2,1/('Weekly Tracker'!$E$2:$E$766=$A144)/('Weekly Tracker'!$N$2:$N$766<>""),'Weekly Tracker'!$N$2:$N$766),"") | L144: =IFERROR(LOOKUP(2,1/('Weekly Tracker'!$E$2:$E$766=$A144)/('Weekly Tracker'!$O$2:$O$766<>""),'Weekly Tracker'!$O$2:$O$766),"")
A145: PuneethAnna | B145: 919677149869 | F145: =IFERROR(LOOKUP(2,1/('Weekly Tracker'!$E$2:$E$766=$A145)/('Weekly Tracker'!$F$2:$F$766<>""),'Weekly Tracker'!$F$2:$F$766),"") | G145: =IF(F145<>"",LOOKUP(2,1/('Weekly Tracker'!$E$2:$E$766=$A145)/('Weekly Tracker'!$F$2:$F$766<>""),'Weekly Tracker'!$G$2:$G$766),"") | H145: =IFERROR(LOOKUP(2,1/('Weekly Tracker'!$E$2:$E$766=$A145)/('Weekly Tracker'!$H$2:$H$766<>""),'Weekly Tracker'!$H$2:$H$766),"") | I145: =IF(H145<>"",LOOKUP(2,1/('Weekly Tracker'!$E$2:$E$766=$A145)/('Weekly Tracker'!$H$2:$H$766<>""),'Weekly Tracker'!$I$2:$I$766),"") | J145: =IFERROR(LOOKUP(2,1/('Weekly Tracker'!$E$2:$E$766=$A145)/('Weekly Tracker'!$J$2:$J$766<>""),'Weekly Tracker'!$J$2:$J$766),"") | K145: =IFERROR(LOOKUP(2,1/('Weekly Tracker'!$E$2:$E$766=$A145)/('Weekly Tracker'!$N$2:$N$766<>""),'Weekly Tracker'!$N$2:$N$766),"") | L145: =IFERROR(LOOKUP(2,1/('Weekly Tracker'!$E$2:$E$766=$A145)/('Weekly Tracker'!$O$2:$O$766<>""),'Weekly Tracker'!$O$2:$O$766),"")
A146: Manoj Kumar Pandiyan HCL | B146: 919677179790 | F146: =IFERROR(LOOKUP(2,1/('Weekly Tracker'!$E$2:$E$766=$A146)/('Weekly Tracker'!$F$2:$F$766<>""),'Weekly Tracker'!$F$2:$F$766),"") | G146: =IF(F146<>"",LOOKUP(2,1/('Weekly Tracker'!$E$2:$E$766=$A146)/('Weekly Tracker'!$F$2:$F$766<>""),'Weekly Tracker'!$G$2:$G$766),"") | H146: =IFERROR(LOOKUP(2,1/('Weekly Tracker'!$E$2:$E$766=$A146)/('Weekly Tracker'!$H$2:$H$766<>""),'Weekly Tracker'!$H$2:$H$766),"") | I146: =IF(H146<>"",LOOKUP(2,1/('Weekly Tracker'!$E$2:$E$766=$A146)/('Weekly Tracker'!$H$2:$H$766<>""),'Weekly Tracker'!$I$2:$I$766),"") | J146: =IFERROR(LOOKUP(2,1/('Weekly Tracker'!$E$2:$E$766=$A146)/('Weekly Tracker'!$J$2:$J$766<>""),'Weekly Tracker'!$J$2:$J$766),"") | K146: =IFERROR(LOOKUP(2,1/('Weekly Tracker'!$E$2:$E$766=$A146)/('Weekly Tracker'!$N$2:$N$766<>""),'Weekly Tracker'!$N$2:$N$766),"") | L146: =IFERROR(LOOKUP(2,1/('Weekly Tracker'!$E$2:$E$766=$A146)/('Weekly Tracker'!$O$2:$O$766<>""),'Weekly Tracker'!$O$2:$O$766),"")
A147: Dhivya Tiruvengadam Urja | B147: 8940103390 | F147: =IFERROR(LOOKUP(2,1/('Weekly Tracker'!$E$2:$E$766=$A147)/('Weekly Tracker'!$F$2:$F$766<>""),'Weekly Tracker'!$F$2:$F$766),"") | G147: =IF(F147<>"",LOOKUP(2,1/('Weekly Tracker'!$E$2:$E$766=$A147)/('Weekly Tracker'!$F$2:$F$766<>""),'Weekly Tracker'!$G$2:$G$766),"") | H147: =IFERROR(LOOKUP(2,1/('Weekly Tracker'!$E$2:$E$766=$A147)/('Weekly Tracker'!$H$2:$H$766<>""),'Weekly Tracker'!$H$2:$H$766),"") | I147: =IF(H147<>"",LOOKUP(2,1/('Weekly Tracker'!$E$2:$E$766=$A147)/('Weekly Tracker'!$H$2:$H$766<>""),'Weekly Tracker'!$I$2:$I$766),"") | J147: =IFERROR(LOOKUP(2,1/('Weekly Tracker'!$E$2:$E$766=$A147)/('Weekly Tracker'!$J$2:$J$766<>""),'Weekly Tracker'!$J$2:$J$766),"") | K147: =IFERROR(LOOKUP(2,1/('Weekly Tracker'!$E$2:$E$766=$A147)/('Weekly Tracker'!$N$2:$N$766<>""),'Weekly Tracker'!$N$2:$N$766),"") | L147: =IFERROR(LOOKUP(2,1/('Weekly Tracker'!$E$2:$E$766=$A147)/('Weekly Tracker'!$O$2:$O$766<>""),'Weekly Tracker'!$O$2:$O$766),"")
...

Sheet Read Me
A1: QNET 2026 SALES TRACKER – HOW TO USE
A3: 1. Weekly Tracker: Starting from AUG Week 31, select the Sales Month/Week and then select a Name from the dropdown.
A4: 2. Info: Enter the response in Info. Enter Info_Date when you make the update. The Main sheet will pull the latest non-empty Info response/date for that Name.
A5: 3. Invite: Enter the response in Invite and Invite_Date. The Main sheet will pull the latest non-empty Invite response/date.
A6: 4. Plans: Enter the response in Plan. The Main sheet will pull the latest non-empty Plan response.
A7: 5. Comments & Notes: Enter these against the Name in Weekly Tracker. The latest non-empty value is shown in Main.
A8: 6. New Numbers: Use the New Numbers sheet for new contacts. Enter Name, Number, Connection and Location. Then add the new person as a new row in Main so they become part of the master Name dropdown.
A9: 7. Dashboard: Shows weekly and monthly counts for Info, Invite, Plans and New Numbers. Charts update when you enter tracker data.
A10: 8. Dates: The workbook is designed for August–December 2026, following the provided QNET Sales Month Calendar (Week 31 to Week 52).
A11: 9. Important: Excel formulas update the Main sheet when the workbook recalculates. For a permanent timestamp that never changes, enter the actual update date in Info_Date / Invite_Date rather than using TODAY().

Sheet Dashboard
A1: QNET 2026 SALES DASHBOARD | J1: KPI
J2: Total Contacts | K2: =COUNTA(Main!$A$2:$A$1645)
A3: Weekly Progress | J3: Info Updates | K3: =COUNTIF('Weekly Tracker'!$F$2:$F$2001,"<>")
A4: Week | B4: Start | C4: End | D4: Info | E4: Invite | F4: Plans | G4: New Numbers | H4: Total Activity | J4: Invite Updates | K4: =COUNTIF('Weekly Tracker'!$H$2:$H$2001,"<>")
A5: 31 | B5: 46234 | C5: 46240 | D5: =COUNTIFS('Weekly Tracker'!$D$2:$D$766,$A5,'Weekly Tracker'!$F$2:$F$766,"<>") | E5: =COUNTIFS('Weekly Tracker'!$D$2:$D$766,$A5,'Weekly Tracker'!$H$2:$H$766,"<>") | F5: =COUNTIFS('Weekly Tracker'!$D$2:$D$766,$A5,'Weekly Tracker'!$J$2:$J$766,"<>") | G5: =COUNTIFS('Weekly Tracker'!$D$2:$D$766,$A5,'Weekly Tracker'!$K$2:$K$766,"<>") | H5: =SUM(D5:G5) | J5: Plan Updates | K5: =COUNTIF('Weekly Tracker'!$J$2:$J$2001,"<>")
A6: 32 | B6: 46241 | C6: 46247 | D6: =COUNTIFS('Weekly Tracker'!$D$2:$D$766,$A6,'Weekly Tracker'!$F$2:$F$766,"<>") | E6: =COUNTIFS('Weekly Tracker'!$D$2:$D$766,$A6,'Weekly Tracker'!$H$2:$H$766,"<>") | F6: =COUNTIFS('Weekly Tracker'!$D$2:$D$766,$A6,'Weekly Tracker'!$J$2:$J$766,"<>") | G6: =COUNTIFS('Weekly Tracker'!$D$2:$D$766,$A6,'Weekly Tracker'!$K$2:$K$766,"<>") | H6: =SUM(D6:G6) | J6: New Numbers | K6: =COUNTIF('New Numbers'!$D$2:$D$501,"<>")
A7: 33 | B7: 46248 | C7: 46254 | D7: =COUNTIFS('Weekly Tracker'!$D$2:$D$766,$A7,'Weekly Tracker'!$F$2:$F$766,"<>") | E7: =COUNTIFS('Weekly Tracker'!$D$2:$D$766,$A7,'Weekly Tracker'!$H$2:$H$766,"<>") | F7: =COUNTIFS('Weekly Tracker'!$D$2:$D$766,$A7,'Weekly Tracker'!$J$2:$J$766,"<>") | G7: =COUNTIFS('Weekly Tracker'!$D$2:$D$766,$A7,'Weekly Tracker'!$K$2:$K$766,"<>") | H7: =SUM(D7:G7)
A8: 34 | B8: 46255 | C8: 46261 | D8: =COUNTIFS('Weekly Tracker'!$D$2:$D$766,$A8,'Weekly Tracker'!$F$2:$F$766,"<>") | E8: =COUNTIFS('Weekly Tracker'!$D$2:$D$766,$A8,'Weekly Tracker'!$H$2:$H$766,"<>") | F8: =COUNTIFS('Weekly Tracker'!$D$2:$D$766,$A8,'Weekly Tracker'!$J$2:$J$766,"<>") | G8: =COUNTIFS('Weekly Tracker'!$D$2:$D$766,$A8,'Weekly Tracker'!$K$2:$K$766,"<>") | H8: =SUM(D8:G8)
A9: 35 | B9: 46262 | C9: 46268 | D9: =COUNTIFS('Weekly Tracker'!$D$2:$D$766,$A9,'Weekly Tracker'!$F$2:$F$766,"<>") | E9: =COUNTIFS('Weekly Tracker'!$D$2:$D$766,$A9,'Weekly Tracker'!$H$2:$H$766,"<>") | F9: =COUNTIFS('Weekly Tracker'!$D$2:$D$766,$A9,'Weekly Tracker'!$J$2:$J$766,"<>") | G9: =COUNTIFS('Weekly Tracker'!$D$2:$D$766,$A9,'Weekly Tracker'!$K$2:$K$766,"<>") | H9: =SUM(D9:G9)
A10: 36 | B10: 46269 | C10: 46275 | D10: =COUNTIFS('Weekly Tracker'!$D$2:$D$766,$A10,'Weekly Tracker'!$F$2:$F$766,"<>") | E10: =COUNTIFS('Weekly Tracker'!$D$2:$D$766,$A10,'Weekly Tracker'!$H$2:$H$766,"<>") | F10: =COUNTIFS('Weekly Tracker'!$D$2:$D$766,$A10,'Weekly Tracker'!$J$2:$J$766,"<>") | G10: =COUNTIFS('Weekly Tracker'!$D$2:$D$766,$A10,'Weekly Tracker'!$K$2:$K$766,"<>") | H10: =SUM(D10:G10)
A11: 37 | B11: 46276 | C11: 46282 | D11: =COUNTIFS('Weekly Tracker'!$D$2:$D$766,$A11,'Weekly Tracker'!$F$2:$F$766,"<>") | E11: =COUNTIFS('Weekly Tracker'!$D$2:$D$766,$A11,'Weekly Tracker'!$H$2:$H$766,"<>") | F11: =COUNTIFS('Weekly Tracker'!$D$2:$D$766,$A11,'Weekly Tracker'!$J$2:$J$766,"<>") | G11: =COUNTIFS('Weekly Tracker'!$D$2:$D$766,$A11,'Weekly Tracker'!$K$2:$K$766,"<>") | H11: =SUM(D11:G11)
A12: 38 | B12: 46283 | C12: 46289 | D12: =COUNTIFS('Weekly Tracker'!$D$2:$D$766,$A12,'Weekly Tracker'!$F$2:$F$766,"<>") | E12: =COUNTIFS('Weekly Tracker'!$D$2:$D$766,$A12,'Weekly Tracker'!$H$2:$H$766,"<>") | F12: =COUNTIFS('Weekly Tracker'!$D$2:$D$766,$A12,'Weekly Tracker'!$J$2:$J$766,"<>") | G12: =COUNTIFS('Weekly Tracker'!$D$2:$D$766,$A12,'Weekly Tracker'!$K$2:$K$766,"<>") | H12: =SUM(D12:G12)
A13: 39 | B13: 46290 | C13: 46296 | D13: =COUNTIFS('Weekly Tracker'!$D$2:$D$766,$A13,'Weekly Tracker'!$F$2:$F$766,"<>") | E13: =COUNTIFS('Weekly Tracker'!$D$2:$D$766,$A13,'Weekly Tracker'!$H$2:$H$766,"<>") | F13: =COUNTIFS('Weekly Tracker'!$D$2:$D$766,$A13,'Weekly Tracker'!$J$2:$J$766,"<>") | G13: =COUNTIFS('Weekly Tracker'!$D$2:$D$766,$A13,'Weekly Tracker'!$K$2:$K$766,"<>") | H13: =SUM(D13:G13)
A14: 40 | B14: 46297 | C14: 46303 | D14: =COUNTIFS('Weekly Tracker'!$D$2:$D$766,$A14,'Weekly Tracker'!$F$2:$F$766,"<>") | E14: =COUNTIFS('Weekly Tracker'!$D$2:$D$766,$A14,'Weekly Tracker'!$H$2:$H$766,"<>") | F14: =COUNTIFS('Weekly Tracker'!$D$2:$D$766,$A14,'Weekly Tracker'!$J$2:$J$766,"<>") | G14: =COUNTIFS('Weekly Tracker'!$D$2:$D$766,$A14,'Weekly Tracker'!$K$2:$K$766,"<>") | H14: =SUM(D14:G14)
A15: 41 | B15: 46304 | C15: 46310 | D15: =COUNTIFS('Weekly Tracker'!$D$2:$D$766,$A15,'Weekly Tracker'!$F$2:$F$766,"<>") | E15: =COUNTIFS('Weekly Tracker'!$D$2:$D$766,$A15,'Weekly Tracker'!$H$2:$H$766,"<>") | F15: =COUNTIFS('Weekly Tracker'!$D$2:$D$766,$A15,'Weekly Tracker'!$J$2:$J$766,"<>") | G15: =COUNTIFS('Weekly Tracker'!$D$2:$D$766,$A15,'Weekly Tracker'!$K$2:$K$766,"<>") | H15: =SUM(D15:G15)
A16: 42 | B16: 46311 | C16: 46317 | D16: =COUNTIFS('Weekly Tracker'!$D$2:$D$766,$A16,'Weekly Tracker'!$F$2:$F$766,"<>") | E16: =COUNTIFS('Weekly Tracker'!$D$2:$D$766,$A16,'Weekly Tracker'!$H$2:$H$766,"<>") | F16: =COUNTIFS('Weekly Tracker'!$D$2:$D$766,$A16,'Weekly Tracker'!$J$2:$J$766,"<>") | G16: =COUNTIFS('Weekly Tracker'!$D$2:$D$766,$A16,'Weekly Tracker'!$K$2:$K$766,"<>") | H16: =SUM(D16:G16)
A17: 43 | B17: 46318 | C17: 46324 | D17: =COUNTIFS('Weekly Tracker'!$D$2:$D$766,$A17,'Weekly Tracker'!$F$2:$F$766,"<>") | E17: =COUNTIFS('Weekly Tracker'!$D$2:$D$766,$A17,'Weekly Tracker'!$H$2:$H$766,"<>") | F17: =COUNTIFS('Weekly Tracker'!$D$2:$D$766,$A17,'Weekly Tracker'!$J$2:$J$766,"<>") | G17: =COUNTIFS('Weekly Tracker'!$D$2:$D$766,$A17,'Weekly Tracker'!$K$2:$K$766,"<>") | H17: =SUM(D17:G17)
A18: 44 | B18: 46325 | C18: 46331 | D18: =COUNTIFS('Weekly Tracker'!$D$2:$D$766,$A18,'Weekly Tracker'!$F$2:$F$766,"<>") | E18: =COUNTIFS('Weekly Tracker'!$D$2:$D$766,$A18,'Weekly Tracker'!$H$2:$H$766,"<>") | F18: =COUNTIFS('Weekly Tracker'!$D$2:$D$766,$A18,'Weekly Tracker'!$J$2:$J$766,"<>") | G18: =COUNTIFS('Weekly Tracker'!$D$2:$D$766,$A18,'Weekly Tracker'!$K$2:$K$766,"<>") | H18: =SUM(D18:G18)
... A26: 52 | B26: 46381 | C26: 46387 | D26: =COUNTIFS('Weekly Tracker'!$D$2:$D$766,$A26,'Weekly Tracker'!$F$2:$F$766,"<>") | E26: =COUNTIFS('Weekly Tracker'!$D$2:$D$766,$A26,'Weekly Tracker'!$H$2:$H$766,"<>") | F26: =COUNTIFS('Weekly Tracker'!$D$2:$D$766,$A26,'Weekly Tracker'!$J$2:$J$766,"<>") | G26: =COUNTIFS('Weekly Tracker'!$D$2:$D$766,$A26,'Weekly Tracker'!$K$2:$K$766,"<>") | H26: =SUM(D26:G26)
A29: Monthly Progress
A30: Month | B30: Info | C30: Invite | D30: Plans | E30: New Numbers | F30: Total Activity
A31: AUG | B31: =COUNTIFS('Weekly Tracker'!$C$2:$C$766,"AUG",'Weekly Tracker'!$F$2:$F$766,"<>") | C31: =COUNTIFS('Weekly Tracker'!$C$2:$C$766,"AUG",'Weekly Tracker'!$H$2:$H$766,"<>") | D31: =COUNTIFS('Weekly Tracker'!$C$2:$C$766,"AUG",'Weekly Tracker'!$J$2:$J$766,"<>") | E31: =COUNTIFS('Weekly Tracker'!$C$2:$C$766,"AUG",'Weekly Tracker'!$K$2:$K$766,"<>") | F31: =SUM(B31:E31)
A32: SEP | B32: =COUNTIFS('Weekly Tracker'!$C$2:$C$766,"SEP",'Weekly Tracker'!$F$2:$F$766,"<>") | C32: =COUNTIFS('Weekly Tracker'!$C$2:$C$766,"SEP",'Weekly Tracker'!$H$2:$H$766,"<>") | D32: =COUNTIFS('Weekly Tracker'!$C$2:$C$766,"SEP",'Weekly Tracker'!$J$2:$J$766,"<>") | E32: =COUNTIFS('Weekly Tracker'!$C$2:$C$766,"SEP",'Weekly Tracker'!$K$2:$K$766,"<>") | F32: =SUM(B32:E32)
A33: OCT | B33: =COUNTIFS('Weekly Tracker'!$C$2:$C$766,"OCT",'Weekly Tracker'!$F$2:$F$766,"<>") | C33: =COUNTIFS('Weekly Tracker'!$C$2:$C$766,"OCT",'Weekly Tracker'!$H$2:$H$766,"<>") | D33: =COUNTIFS('Weekly Tracker'!$C$2:$C$766,"OCT",'Weekly Tracker'!$J$2:$J$766,"<>") | E33: =COUNTIFS('Weekly Tracker'!$C$2:$C$766,"OCT",'Weekly Tracker'!$K$2:$K$766,"<>") | F33: =SUM(B33:E33)
A34: NOV | B34: =COUNTIFS('Weekly Tracker'!$C$2:$C$766,"NOV",'Weekly Tracker'!$F$2:$F$766,"<>") | C34: =COUNTIFS('Weekly Tracker'!$C$2:$C$766,"NOV",'Weekly Tracker'!$H$2:$H$766,"<>") | D34: =COUNTIFS('Weekly Tracker'!$C$2:$C$766,"NOV",'Weekly Tracker'!$J$2:$J$766,"<>") | E34: =COUNTIFS('Weekly Tracker'!$C$2:$C$766,"NOV",'Weekly Tracker'!$K$2:$K$766,"<>") | F34: =SUM(B34:E34)
A35: DEC | B35: =COUNTIFS('Weekly Tracker'!$C$2:$C$766,"DEC",'Weekly Tracker'!$F$2:$F$766,"<>") | C35: =COUNTIFS('Weekly Tracker'!$C$2:$C$766,"DEC",'Weekly Tracker'!$H$2:$H$766,"<>") | D35: =COUNTIFS('Weekly Tracker'!$C$2:$C$766,"DEC",'Weekly Tracker'!$J$2:$J$766,"<>") | E35: =COUNTIFS('Weekly Tracker'!$C$2:$C$766,"DEC",'Weekly Tracker'!$K$2:$K$766,"<>") | F35: =SUM(B35:E35)

Sheet Lists
A1: Name List | B1: Zone List
A2: Samsung Helpline | B2: Warm
A3: Ragul Urja | B3: HOT
A4: Rajesh ramadoss Urja | B4: Cold
A5: Rajesh Past Urja
A6: Ragul Hit Urja
A7: Rajesh FB
A8: Rakesh Urja
A9: Vinoth Mech
A10: Mani Kandan FB
A11: Mani VJ FB
A12: Niranjan Urja
A13: Anbu Urja
A14: Vinoth Kumar Mech
A15: Manikandan FB
A16: Urjanet
... A1645: Ananth Homebeside

Sheet New Numbers
A1: Sales Month | B1: Week No | C1: Date Added | D1: Name | E1: Contact Number | F1: Connection | G1: Location | H1: Comments | I1: Notes | J1: Added to Main?
J2: No
J3: No
J4: No
J5: No
J6: No
J7: No
J8: No
J9: No
J10: No
J11: No
J12: No
J13: No
... J501: No

Sheet Weekly Tracker
A1: Date | B1: Day | C1: Sales Month | D1: Week No | E1: Name | F1: Info | G1: Info_Date | H1: Invite | I1: Invite_Date | J1: Plan | K1: New Number | L1: New Connection | M1: New Location | N1: Comments | O1: Notes | Q1: DAILY TRACKER
A2: 46235 | B2: Saturday | C2: AUG | D2: 31 | Q2: 01-Aug-2026 to 31-Dec-2026
A3: 46235 | B3: Saturday | C3: AUG | D3: 31 | Q3: Every calendar day has exactly 5 rows. Select a Name from the dropdown and enter your daily activity.
A4: 46235 | B4: Saturday | C4: AUG | D4: 31
A5: 46235 | B5: Saturday | C5: AUG | D5: 31
A6: 46235 | B6: Saturday | C6: AUG | D6: 31
A7: 46236 | B7: Sunday | C7: AUG | D7: 31
A8: 46236 | B8: Sunday | C8: AUG | D8: 31
A9: 46236 | B9: Sunday | C9: AUG | D9: 31
A10: 46236 | B10: Sunday | C10: AUG | D10: 31
A11: 46236 | B11: Sunday | C11: AUG | D11: 31
A12: 46237 | B12: Monday | C12: AUG | D12: 31
A13: 46237 | B13: Monday | C13: AUG | D13: 31
A14: 46237 | B14: Monday | C14: AUG | D14: 31
A15: 46237 | B15: Monday | C15: AUG | D15: 31
... A766: 46387 | B766: Thursday | C766: DEC | D766: 52
